Workbook

Sheet Seguimiento OIT
A1: Requerimientos OIT
A2: Datos del Requerimiento | Q2: Seguimiento de atención de requerimiento y estado del servicio | AH2: Gestión de Renovación
A3: Código | B3: Estado_Tablero | C3: Requerimiento asociado | D3: Indicador PAC | E3: Tipo de Procedimiento | F3: Tipo requerimiento | G3: Tipo de adquisición | H3: Denominación | I3: Hoja de Ruta asociadas | J3: Servicios - Bienes incluidos | K3: Área OIT | L3: Coordinador | M3: Responsable | N3: Área Usuaria MEF | O3: Monto | P3: Fecha de solicitud | Q3: Estado_Requerimiento/Contrato | R3: Area_asignada | S3: Fecha de ultimo estado | T3: Cantidad_dias_ en área asignada | U3: Documento de contratación | V3: Nro de documento | W3: Fecha de suscripción o notificación | X3: Empresa(s) contratada | Y3: Reponsable de ejecución | Z3: Estado_servicio | AA3: Fecha de inicio_vigencia | AB3: Fecha de fin_vigencia | AC3: Vigencia | AD3: Dias sin servicio | AE3: Comentarios_atencion_requerimiento | AF3: Comentarios_Servicio (Ejecución) | AG3: Enlace de Repositorio | AH3: ¿Requiere Renovar? | AI3: Estado renovación | AJ3: HR renovación | AK3: Fecha_Inicio_Renov | AL3: Fecha_Fin_Renov
A4: REQ-2026-0001 | B4: =IF(OR(Q4="Desistido",Q4="No corresponde Atención OGTI",Q4="Para reformulación",Q4="Paralizado",Q4="-",Z4="Renovado",AND(AH4="NO",Z4="Culminado")),"NO","SI") -> NO | C4: - | D4: NO | E4: Contratación Directa | F4: Renovación | G4: Bienes | H4: Adquisición de licencias de software para Central Telefónica destinadas al uso de softphone para la Defensoría del Contribuyente y Usuario Aduanero del MEF. | I4: 074877-2026 | J4: Licencias Softphone para central telefonica | K4: Telefonía | L4: Isaias Bolivar Reaño | M4: Isaias Bolivar Reaño | N4: Defensoría del Contribuyente y Usuario Aduanero | O4: 6808.64 | P4: 46113 | Q4: Ejecutado | R4: - | S4: - | T4: =IFERROR(IF(OR(Q4="Ejecutado",Q4="No corresponde atención OGTI",Q4="Desistido",Q4="-",Q4="Para reformulación"),"-",IF(OR(S4="-",S4=""),"Falta fecha_estado",NETWORKDAYS(S4,TODAY(),{"02/04/2026";"03/04/2026";"30/06/2026"}))),"-") -> - | U4: Orden de Compra | V4: 0000149-2026 | W4: 46154 | X4: E-BUSINESS DISTRIBUTION PERU S.A | Y4: Isaias Bolivar Reaño | Z4: =IFERROR(IF(Q4="-","-",IF(Q4="Proceso de implementación/Activación/Entrega","Proceso de implementación/Activación/Entrega",IF(OR(Q4="Desistido",Q4="No corresponde atención OGTI",Q4="Para reformulación"),Q4,IF(AND(Q4="Ejecutado",AA4="No aplica",AB4="No Aplica"),"Culminado",IF(Q4="Ejecutado",IF(AND(AC4="-",G4="Bienes"),"Culminado",IF(AC4="-","Falta informacion",IF(AND(AB4-TODAY()>=0,AB4-TODAY()<=90),"Vigente_por vencer",IF(AND(AH4<>"SI",AB4<TODAY()),"Culminado",IF(AND(AH4="SI",AB4<TODAY(),OR(AK4="Sin Registro",AL4="Sin Registro")),"Vencido",IF(AND(AH4="SI",AB4<TODAY(),AK4>AA4,AL4>AB4),"Renovado","Vigente")))))),"En tramite"))))),"-") -> Culminado | AA4: - | AB4: - | AC4: =IFERROR(IF(OR(AA4="-",AA4="",AB4="-",AB4=""),"-",CONCATENATE('Seguimiento OIT'!AB4-'Seguimiento OIT'!AA4+1," dias")),"-") -> - | AD4: =IFERROR(IF(Z4="Vencido",(TODAY()-AB4)+1,"-"),"-") -> - | AE4: - | AF4: Licencias no tienen vigencia. Garantia del 12-05-26 al 11-05-27) | AG4: https://mefgobpe1.sharepoint.com/:f:/t/DireccindelaOficinadeInfraestructuraTecnolgica/IgAMjzQ2CwrsSrZrpbNNuH6TAexSvIZkaygR0PcCrH9EkUg?e=bpppHT | AH4: NO | AI4: =IFERROR(IF(AH4="SI",VLOOKUP(A4,$C$4:$AL$151,15,FALSE),"-"),"Sin tramite") -> - | AJ4: =IFERROR(IF(AH4="SI",VLOOKUP(A4,$C$4:$AL$151,7,FALSE),"-"),"Sin HR") -> - | AK4: =IF(AH4="SI",IFERROR(IF(VLOOKUP(A4,$C$4:$AL$151,25,FALSE)="","Sin registro",VLOOKUP(A4,$C$4:$AL$151,25,FALSE)),"Sin registro"),"-") -> - | AL4: =IF(AH4="SI",IFERROR(IF(VLOOKUP(A4,$C$4:$AL$151,26,FALSE)="","Sin registro",VLOOKUP(A4,$C$4:$AL$151,26,FALSE)),"Sin registro"),"-") -> -
A5: REQ-2026-0002 | B5: =IF(OR(Q5="Desistido",Q5="No corresponde Atención OGTI",Q5="Para reformulación",Q5="Paralizado",Q5="-",Z5="Renovado",AND(AH5="NO",Z5="Culminado")),"NO","SI") -> NO | C5: - | D5: NO | E5: Contratación Directa | F5: Nuevo requerimiento | G5: Bienes | H5: Adquisición de audífonos para la Defensoría del Contribuyente y Usuario Aduanero del MEF | I5: 074848-2026 | J5: Audifonos (12 unidades) | K5: Telefonía | L5: Isaias Bolivar Reaño | M5: Isaias Bolivar Reaño | N5: Defensoría del Contribuyente y Usuario Aduanero | O5: 1192.2 | P5: 46113 | Q5: Ejecutado | R5: - | S5: - | T5: =IFERROR(IF(OR(Q5="Ejecutado",Q5="No corresponde atención OGTI",Q5="Desistido",Q5="-",Q5="Para reformulación"),"-",IF(OR(S5="-",S5=""),"Falta fecha_estado",NETWORKDAYS(S5,TODAY(),{"02/04/2026";"03/04/2026";"30/06/2026"}))),"-") -> - | U5: Orden de Compra | V5: 0000115-2026 | W5: 46129 | X5: VML COMPUTER S.A.C. | Y5: Isaias Bolivar Reaño | Z5: =IFERROR(IF(Q5="-","-",IF(Q5="Proceso de implementación/Activación/Entrega","Proceso de implementación/Activación/Entrega",IF(OR(Q5="Desistido",Q5="No corresponde atención OGTI",Q5="Para reformulación"),Q5,IF(AND(Q5="Ejecutado",AA5="No aplica",AB5="No Aplica"),"Culminado",IF(Q5="Ejecutado",IF(AND(AC5="-",G5="Bienes"),"Culminado",IF(AC5="-","Falta informacion",IF(AND(AB5-TODAY()>=0,AB5-TODAY()<=90),"Vigente_por vencer",IF(AND(AH5<>"SI",AB5<TODAY()),"Culminado",IF(AND(AH5="SI",AB5<TODAY(),OR(AK5="Sin Registro",AL5="Sin Registro")),"Vencido",IF(AND(AH5="SI",AB5<TODAY(),AK5>AA5,AL5>AB5),"Renovado","Vigente")))))),"En tramite"))))),"-") -> Culminado | AA5: - | AB5: - | AC5: =IFERROR(IF(OR(AA5="-",AA5="",AB5="-",AB5=""),"-",CONCATENATE('Seguimiento OIT'!AB5-'Seguimiento OIT'!AA5+1," dias")),"-") -> - | AD5: =IFERROR(IF(Z5="Vencido",(TODAY()-AB5)+1,"-"),"-") -> - | AE5: - | AF5: Conforrmidad HR 090493-2026 | AG5: https://mefgobpe1.sharepoint.com/:f:/t/DireccindelaOficinadeInfraestructuraTecnolgica/IgAMjzQ2CwrsSrZrpbNNuH6TAexSvIZkaygR0PcCrH9EkUg?e=bpppHT | AH5: NO | AI5: =IFERROR(IF(AH5="SI",VLOOKUP(A5,$C$4:$AL$151,15,FALSE),"-"),"Sin tramite") -> - | AJ5: =IFERROR(IF(AH5="SI",VLOOKUP(A5,$C$4:$AL$151,7,FALSE),"-"),"Sin HR") -> - | AK5: =IF(AH5="SI",IFERROR(IF(VLOOKUP(A5,$C$4:$AL$151,25,FALSE)="","Sin registro",VLOOKUP(A5,$C$4:$AL$151,25,FALSE)),"Sin registro"),"-") -> - | AL5: =IF(AH5="SI",IFERROR(IF(VLOOKUP(A5,$C$4:$AL$151,26,FALSE)="","Sin registro",VLOOKUP(A5,$C$4:$AL$151,26,FALSE)),"Sin registro"),"-") -> -
A6: REQ-2026-0003 | B6: =IF(OR(Q6="Desistido",Q6="No corresponde Atención OGTI",Q6="Para reformulación",Q6="Paralizado",Q6="-",Z6="Renovado",AND(AH6="NO",Z6="Culminado")),"NO","SI") -> SI | C6: - | D6: NO | E6: Contratación Directa | F6: Nuevo requerimiento | G6: Servicios | H6: Contratación de una Cuenta Teams Room para la Sala de Reuniones de la Dirección General de Abastecimiento | I6: *082319-2026 (Requerimiento) *033456-2026 (Antecedente 01) *178871-2025 (Antecedente 02) | J6: Teams Room | K6: Soporte Tecnico | L6: Napoleon Alva Vasquez | M6: Ronald Yrupailla Diaz | N6: Dirección General de Abastecimiento | O6: 2315 | P6: 46125 | Q6: Ejecutado | R6: - | S6: - | T6: =IFERROR(IF(OR(Q6="Ejecutado",Q6="No corresponde atención OGTI",Q6="Desistido",Q6="-",Q6="Para reformulación"),"-",IF(OR(S6="-",S6=""),"Falta fecha_estado",NETWORKDAYS(S6,TODAY(),{"02/04/2026";"03/04/2026";"30/06/2026"}))),"-") -> - | U6: Orden de Servicio | V6: 0002117-2026 | W6: 46139 | X6: DAILY TECHNOLOGY S.A.C | Y6: Ronald Yrupailla Diaz | Z6: =IFERROR(IF(Q6="-","-",IF(Q6="Proceso de implementación/Activación/Entrega","Proceso de implementación/Activación/Entrega",IF(OR(Q6="Desistido",Q6="No corresponde atención OGTI",Q6="Para reformulación"),Q6,IF(AND(Q6="Ejecutado",AA6="No aplica",AB6="No Aplica"),"Culminado",IF(Q6="Ejecutado",IF(AND(AC6="-",G6="Bienes"),"Culminado",IF(AC6="-","Falta informacion",IF(AND(AB6-TODAY()>=0,AB6-TODAY()<=90),"Vigente_por vencer",IF(AND(AH6<>"SI",AB6<TODAY()),"Culminado",IF(AND(AH6="SI",AB6<TODAY(),OR(AK6="Sin Registro",AL6="Sin Registro")),"Vencido",IF(AND(AH6="SI",AB6<TODAY(),AK6>AA6,AL6>AB6),"Renovado","Vigente")))))),"En tramite"))))),"-") -> Vigente | AA6: 46141 | AB6: 46505 | AC6: =IFERROR(IF(OR(AA6="-",AA6="",AB6="-",AB6=""),"-",CONCATENATE('Seguimiento OIT'!AB6-'Seguimiento OIT'!AA6+1," dias")),"-") -> 365 dias | AD6: =IFERROR(IF(Z6="Vencido",(TODAY()-AB6)+1,"-"),"-") -> - | AE6: - | AF6: Conforrmidad HR 096621-2026 | AG6: https://mefgobpe1.sharepoint.com/:f:/t/DireccindelaOficinadeInfraestructuraTecnolgica/IgAZXGbnCkU6TontNlj_5zofAbPXwRd4mqf2ka9BS6cc7LU?e=Ejjkds | AH6: NO | AI6: =IFERROR(IF(AH6="SI",VLOOKUP(A6,$C$4:$AL$151,15,FALSE),"-"),"Sin tramite") -> - | AJ6: =IFERROR(IF(AH6="SI",VLOOKUP(A6,$C$4:$AL$151,7,FALSE),"-"),"Sin HR") -> - | AK6: =IF(AH6="SI",IFERROR(IF(VLOOKUP(A6,$C$4:$AL$151,25,FALSE)="","Sin registro",VLOOKUP(A6,$C$4:$AL$151,25,FALSE)),"Sin registro"),"-") -> - | AL6: =IF(AH6="SI",IFERROR(IF(VLOOKUP(A6,$C$4:$AL$151,26,FALSE)="","Sin registro",VLOOKUP(A6,$C$4:$AL$151,26,FALSE)),"Sin registro"),"-") -> -
A7: REQ-2026-0004 | B7: =IF(OR(Q7="Desistido",Q7="No corresponde Atención OGTI",Q7="Para reformulación",Q7="Paralizado",Q7="-",Z7="Renovado",AND(AH7="NO",Z7="Culminado")),"NO","SI") -> NO | C7: - | D7: NO | E7: Contratación Directa | F7: Nuevo requerimiento | G7: Bienes | H7: Adquisición de puntero laser inalámbrico para presentación de diapositivas y extensor inalámbrico de señal HDMI/VGA | I7: *082266-2026 (Requerimiento) *060008-2026 (Apoyo presupuestal) | J7: *Puntero Laser USB *Extensor inalámbrico de señal HDMI/VGA | K7: Soporte Tecnico | L7: Napoleon Alva Vasquez | M7: Ronald Yrupailla Diaz | N7: Dirección General de Abastecimiento | O7: 1490 | P7: 46125 | Q7: Ejecutado | R7: - | S7: - | T7: =IFERROR(IF(OR(Q7="Ejecutado",Q7="No corresponde atención OGTI",Q7="Desistido",Q7="-",Q7="Para reformulación"),"-",IF(OR(S7="-",S7=""),"Falta fecha_estado",NETWORKDAYS(S7,TODAY(),{"02/04/2026";"03/04/2026";"30/06/2026"}))),"-") -> - | U7: Orden de Compra | V7: 0000114-2026 | W7: 46128 | X7: ELECTRONICA MUSICAL SOCIEDAD ANONIMA CERRADA | Y7: Ronald Yrupailla Diaz | Z7: =IFERROR(IF(Q7="-","-",IF(Q7="Proceso de implementación/Activación/Entrega","Proceso de implementación/Activación/Entrega",IF(OR(Q7="Desistido",Q7="No corresponde atención OGTI",Q7="Para reformulación"),Q7,IF(AND(Q7="Ejecutado",AA7="No aplica",AB7="No Aplica"),"Culminado",IF(Q7="Ejecutado",IF(AND(AC7="-",G7="Bienes"),"Culminado",IF(AC7="-","Falta informacion",IF(AND(AB7-TODAY()>=0,AB7-TODAY()<=90),"Vigente_por vencer",IF(AND(AH7<>"SI",AB7<TODAY()),"Culminado",IF(AND(AH7="SI",AB7<TODAY(),OR(AK7="Sin Registro",AL7="Sin Registro")),"Vencido",IF(AND(AH7="SI",AB7<TODAY(),AK7>AA7,AL7>AB7),"Renovado","Vigente")))))),"En tramite"))))),"-") -> Culminado | AA7: - | AB7: - | AC7: =IFERROR(IF(OR(AA7="-",AA7="",AB7="-",AB7=""),"-",CONCATENATE('Seguimiento OIT'!AB7-'Seguimiento OIT'!AA7+1," dias")),"-") -> - | AD7: =IFERROR(IF(Z7="Vencido",(TODAY()-AB7)+1,"-"),"-") -> - | AE7: - | AF7: Conforrmidad HR 090442-2026 | AG7: https://mefgobpe1.sharepoint.com/:f:/t/DireccindelaOficinadeInfraestructuraTecnolgica/IgDhJgwKBPIITJaNuzbU7fwMAWJyPbtURdvydZOXH0YHWGA?e=5X4nby | AH7: NO | AI7: =IFERROR(IF(AH7="SI",VLOOKUP(A7,$C$4:$AL$151,15,FALSE),"-"),"Sin tramite") -> - | AJ7: =IFERROR(IF(AH7="SI",VLOOKUP(A7,$C$4:$AL$151,7,FALSE),"-"),"Sin HR") -> - | AK7: =IF(AH7="SI",IFERROR(IF(VLOOKUP(A7,$C$4:$AL$151,25,FALSE)="","Sin registro",VLOOKUP(A7,$C$4:$AL$151,25,FALSE)),"Sin registro"),"-") -> - | AL7: =IF(AH7="SI",IFERROR(IF(VLOOKUP(A7,$C$4:$AL$151,26,FALSE)="","Sin registro",VLOOKUP(A7,$C$4:$AL$151,26,FALSE)),"Sin registro"),"-") -> -
A8: REQ-2026-0005 | B8: =IF(OR(Q8="Desistido",Q8="No corresponde Atención OGTI",Q8="Para reformulación",Q8="Paralizado",Q8="-",Z8="Renovado",AND(AH8="NO",Z8="Culminado")),"NO","SI") -> NO | C8: - | D8: NO | E8: Contratación Directa | F8: Nuevo requerimiento | G8: Bienes | H8: Adquisición de Pantalla Interactiva para la Dirección General de Presupuesto Público (DGPP). | I8: 048517-2026 | J8: Pantalla interactiva | K8: Soporte Tecnico | L8: Napoleon Alva Vasquez | M8: Ronald Yrupailla Diaz | N8: Dirección General de Presupuesto Público | O8: 23529.29 | P8: 46086 | Q8: Ejecutado | R8: - | S8: - | T8: =IFERROR(IF(OR(Q8="Ejecutado",Q8="No corresponde atención OGTI",Q8="Desistido",Q8="-",Q8="Para reformulación"),"-",IF(OR(S8="-",S8=""),"Falta fecha_estado",NETWORKDAYS(S8,TODAY(),{"02/04/2026";"03/04/2026";"30/06/2026"}))),"-") -> - | U8: Orden de Compra | V8: 0000077-2026 | W8: 46107 | X8: COMPU CENTER BUSSINES S.A.C. | Y8: Napoleon Alva Vasquez | Z8: =IFERROR(IF(Q8="-","-",IF(Q8="Proceso de implementación/Activación/Entrega","Proceso de implementación/Activación/Entrega",IF(OR(Q8="Desistido",Q8="No corresponde atención OGTI",Q8="Para reformulación"),Q8,IF(AND(Q8="Ejecutado",AA8="No aplica",AB8="No Aplica"),"Culminado",IF(Q8="Ejecutado",IF(AND(AC8="-",G8="Bienes"),"Culminado",IF(AC8="-","Falta informacion",IF(AND(AB8-TODAY()>=0,AB8-TODAY()<=90),"Vigente_por vencer",IF(AND(AH8<>"SI",AB8<TODAY()),"Culminado",IF(AND(AH8="SI",AB8<TODAY(),OR(AK8="Sin Registro",AL8="Sin Registro")),"Vencido",IF(AND(AH8="SI",AB8<TODAY(),AK8>AA8,AL8>AB8),"Renovado","Vigente")))))),"En tramite"))))),"-") -> Culminado | AA8: - | AB8: - | AC8: =IFERROR(IF(OR(AA8="-",AA8="",AB8="-",AB8=""),"-",CONCATENATE('Seguimiento OIT'!AB8-'Seguimiento OIT'!AA8+1," dias")),"-") -> - | AD8: =IFERROR(IF(Z8="Vencido",(TODAY()-AB8)+1,"-"),"-") -> - | AE8: - | AF8: Conforrmidad HR 081407-2026 | AG8: https://mefgobpe1.sharepoint.com/:f:/t/DireccindelaOficinadeInfraestructuraTecnolgica/IgAuQUOZDJlsS52DtyJNBD8aAQ9zOl_Ud_ejgD_u3ufWXIQ?e=YafDUj | AH8: NO | AI8: =IFERROR(IF(AH8="SI",VLOOKUP(A8,$C$4:$AL$151,15,FALSE),"-"),"Sin tramite") -> - | AJ8: =IFERROR(IF(AH8="SI",VLOOKUP(A8,$C$4:$AL$151,7,FALSE),"-"),"Sin HR") -> - | AK8: =IF(AH8="SI",IFERROR(IF(VLOOKUP(A8,$C$4:$AL$151,25,FALSE)="","Sin registro",VLOOKUP(A8,$C$4:$AL$151,25,FALSE)),"Sin registro"),"-") -> - | AL8: =IF(AH8="SI",IFERROR(IF(VLOOKUP(A8,$C$4:$AL$151,26,FALSE)="","Sin registro",VLOOKUP(A8,$C$4:$AL$151,26,FALSE)),"Sin registro"),"-") -> -
A9: REQ-2026-0006 | B9: =IF(OR(Q9="Desistido",Q9="No corresponde Atención OGTI",Q9="Para reformulación",Q9="Paralizado",Q9="-",Z9="Renovado",AND(AH9="NO",Z9="Culminado")),"NO","SI") -> NO | C9: - | D9: NO | E9: Contratación Directa | F9: Nuevo requerimiento | G9: Bienes | H9: Adquisición de Pantalla Interactiva para el Tribunal Fiscal del Ministerio de Economía y Finanzas | I9: 033089-2026 | J9: Pantalla interactiva | K9: Soporte Tecnico | L9: Napoleon Alva Vasquez | M9: Ronald Yrupailla Diaz | N9: Tribunal Fiscal | O9: 22956.19 | P9: 46064 | Q9: Ejecutado | R9: - | S9: - | T9: =IFERROR(IF(OR(Q9="Ejecutado",Q9="No corresponde atención OGTI",Q9="Desistido",Q9="-",Q9="Para reformulación"),"-",IF(OR(S9="-",S9=""),"Falta fecha_estado",NETWORKDAYS(S9,TODAY(),{"02/04/2026";"03/04/2026";"30/06/2026"}))),"-") -> - | U9: Orden de Compra | V9: 0000048-2026 | W9: 46083 | X9: COMPU CENTER BUSSINES S.A.C. | Y9: Napoleon Alva Vasquez | Z9: =IFERROR(IF(Q9="-","-",IF(Q9="Proceso de implementación/Activación/Entrega","Proceso de implementación/Activación/Entrega",IF(OR(Q9="Desistido",Q9="No corresponde atención OGTI",Q9="Para reformulación"),Q9,IF(AND(Q9="Ejecutado",AA9="No aplica",AB9="No Aplica"),"Culminado",IF(Q9="Ejecutado",IF(AND(AC9="-",G9="Bienes"),"Culminado",IF(AC9="-","Falta informacion",IF(AND(AB9-TODAY()>=0,AB9-TODAY()<=90),"Vigente_por vencer",IF(AND(AH9<>"SI",AB9<TODAY()),"Culminado",IF(AND(AH9="SI",AB9<TODAY(),OR(AK9="Sin Registro",AL9="Sin Registro")),"Vencido",IF(AND(AH9="SI",AB9<TODAY(),AK9>AA9,AL9>AB9),"Renovado","Vigente")))))),"En tramite"))))),"-") -> Culminado | AA9: - | AB9: - | AC9: =IFERROR(IF(OR(AA9="-",AA9="",AB9="-",AB9=""),"-",CONCATENATE('Seguimiento OIT'!AB9-'Seguimiento OIT'!AA9+1," dias")),"-") -> - | AD9: =IFERROR(IF(Z9="Vencido",(TODAY()-AB9)+1,"-"),"-") -> - | AE9: - | AF9: Conforrmidad HR 056765-2026 | AG9: https://mefgobpe1.sharepoint.com/:f:/t/DireccindelaOficinadeInfraestructuraTecnolgica/IgA4J9G8lX8jTL50cb-xPfgVAYuuw3a9sQa6941P4nOdfms?e=DE2hgt | AH9: NO | AI9: =IFERROR(IF(AH9="SI",VLOOKUP(A9,$C$4:$AL$151,15,FALSE),"-"),"Sin tramite") -> - | AJ9: =IFERROR(IF(AH9="SI",VLOOKUP(A9,$C$4:$AL$151,7,FALSE),"-"),"Sin HR") -> - | AK9: =IF(AH9="SI",IFERROR(IF(VLOOKUP(A9,$C$4:$AL$151,25,FALSE)="","Sin registro",VLOOKUP(A9,$C$4:$AL$151,25,FALSE)),"Sin registro"),"-") -> - | AL9: =IF(AH9="SI",IFERROR(IF(VLOOKUP(A9,$C$4:$AL$151,26,FALSE)="","Sin registro",VLOOKUP(A9,$C$4:$AL$151,26,FALSE)),"Sin registro"),"-") -> -
A10: REQ-2026-0007 | B10: =IF(OR(Q10="Desistido",Q10="No corresponde Atención OGTI",Q10="Para reformulación",Q10="Paralizado",Q10="-",Z10="Renovado",AND(AH10="NO",Z10="Culminado")),"NO","SI") -> SI | C10: - | D10: NO | E10: Contratación Directa | F10: Nuevo requerimiento | G10: Servicios | H10: Servicio de mantenimiento preventivo y correctivo de equipos escáner de gran formato de la Oficina General de Servicios al Usuario (OGSU) | I10: 042907-2026 | J10: Mantenimiento preventivo y correctivo (Escaner IQ X4400) | K10: Soporte Tecnico | L10: Napoleon Alva Vasquez | M10: Ronald Yrupailla Diaz | N10: Oficina General de Servicios al Usuario | O10: 5445.7 | P10: 46103 | Q10: Ejecutado | R10: - | S10: - | T10: =IFERROR(IF(OR(Q10="Ejecutado",Q10="No corresponde atención OGTI",Q10="Desistido",Q10="-",Q10="Para reformulación"),"-",IF(OR(S10="-",S10=""),"Falta fecha_estado",NETWORKDAYS(S10,TODAY(),{"02/04/2026";"03/04/2026";"30/06/2026"}))),"-") -> - | U10: Orden de Servicio | V10: 0001928-2026 | W10: 46125 | X10: GRUPO VENTURA PERU S.A.C. | Y10: Napoleon Alva Vasquez | Z10: =IFERROR(IF(Q10="-","-",IF(Q10="Proceso de implementación/Activación/Entrega","Proceso de implementación/Activación/Entrega",IF(OR(Q10="Desistido",Q10="No corresponde atención OGTI",Q10="Para reformulación"),Q10,IF(AND(Q10="Ejecutado",AA10="No aplica",AB10="No Aplica"),"Culminado",IF(Q10="Ejecutado",IF(AND(AC10="-",G10="Bienes"),"Culminado",IF(AC10="-","Falta informacion",IF(AND(AB10-TODAY()>=0,AB10-TODAY()<=90),"Vigente_por vencer",IF(AND(AH10<>"SI",AB10<TODAY()),"Culminado",IF(AND(AH10="SI",AB10<TODAY(),OR(AK10="Sin Registro",AL10="Sin Registro")),"Vencido",IF(AND(AH10="SI",AB10<TODAY(),AK10>AA10,AL10>AB10),"Renovado","Vigente")))))),"En tramite"))))),"-") -> Vigente | AA10: 46147 | AB10: 46330 | AC10: =IFERROR(IF(OR(AA10="-",AA10="",AB10="-",AB10=""),"-",CONCATENATE('Seguimiento OIT'!AB10-'Seguimiento OIT'!AA10+1," dias")),"-") -> 184 dias | AD10: =IFERROR(IF(Z10="Vencido",(TODAY()-AB10)+1,"-"),"-") -> - | AE10: - | AF10: *Conformidad HR 092550-2026 *Seguimiento a garantia | AG10: https://mefgobpe1.sharepoint.com/:f:/t/DireccindelaOficinadeInfraestructuraTecnolgica/IgAdCBapqOqqRJpyEFJ7XwgXAX0rGkLM2DRJnlRRxk9fGTo?e=7jpXkp | AH10: NO | AI10: =IFERROR(IF(AH10="SI",VLOOKUP(A10,$C$4:$AL$151,15,FALSE),"-"),"Sin tramite") -> - | AJ10: =IFERROR(IF(AH10="SI",VLOOKUP(A10,$C$4:$AL$151,7,FALSE),"-"),"Sin HR") -> - | AK10: =IF(AH10="SI",IFERROR(IF(VLOOKUP(A10,$C$4:$AL$151,25,FALSE)="","Sin registro",VLOOKUP(A10,$C$4:$AL$151,25,FALSE)),"Sin registro"),"-") -> - | AL10: =IF(AH10="SI",IFERROR(IF(VLOOKUP(A10,$C$4:$AL$151,26,FALSE)="","Sin registro",VLOOKUP(A10,$C$4:$AL$151,26,FALSE)),"Sin registro"),"-") -> -
A11: REQ-2026-0008 | B11: =IF(OR(Q11="Desistido",Q11="No corresponde Atención OGTI",Q11="Para reformulación",Q11="Paralizado",Q11="-",Z11="Renovado",AND(AH11="NO",Z11="Culminado")),"NO","SI") -> SI | C11: - | D11: NO | E11: Contratación Directa | F11: Renovación | G11: Servicios | H11: Servicio de suscripción de licencias de software de asistencia inteligente y de automatización de flujos de trabajo de la marca Microsoft | I11: 040448-2026 | J11: *COPILOT 365 (21) *Power Automate Process (02) | K11: Jefatura OIT | L11: José Romucho Sotelo | M11: Ronald Yrupailla Diaz | N11: Oficina General de Tecnologías de la Información | O11: 43764.05 | P11: 46073 | Q11: Ejecutado | R11: - | S11: - | T11: =IFERROR(IF(OR(Q11="Ejecutado",Q11="No corresponde atención OGTI",Q11="Desistido",Q11="-",Q11="Para reformulación"),"-",IF(OR(S11="-",S11=""),"Falta fecha_estado",NETWORKDAYS(S11,TODAY(),{"02/04/2026";"03/04/2026";"30/06/2026"}))),"-") -> - | U11: Orden de Servicio | V11: 0001422-2026 | W11: 46099 | X11: SEIDOR TECHNOLOGIES PERU S.A.C. | Y11: José Romucho Sotelo | Z11: =IFERROR(IF(Q11="-","-",IF(Q11="Proceso de implementación/Activación/Entrega","Proceso de implementación/Activación/Entrega",IF(OR(Q11="Desistido",Q11="No corresponde atención OGTI",Q11="Para reformulación"),Q11,IF(AND(Q11="Ejecutado",AA11="No aplica",AB11="No Aplica"),"Culminado",IF(Q11="Ejecutado",IF(AND(AC11="-",G11="Bienes"),"Culminado",IF(AC11="-","Falta informacion",IF(AND(AB11-TODAY()>=0,AB11-TODAY()<=90),"Vigente_por vencer",IF(AND(AH11<>"SI",AB11<TODAY()),"Culminado",IF(AND(AH11="SI",AB11<TODAY(),OR(AK11="Sin Registro",AL11="Sin Registro")),"Vencido",IF(AND(AH11="SI",AB11<TODAY(),AK11>AA11,AL11>AB11),"Renovado","Vigente")))))),"En tramite"))))),"-") -> Vigente | AA11: 46104 | AB11: 46468 | AC11: =IFERROR(IF(OR(AA11="-",AA11="",AB11="-",AB11=""),"-",CONCATENATE('Seguimiento OIT'!AB11-'Seguimiento OIT'!AA11+1," dias")),"-") -> 365 dias | AD11: =IFERROR(IF(Z11="Vencido",(TODAY()-AB11)+1,"-"),"-") -> - | AE11: - | AF11: *Conformidad HR 072061-2026 | AG11: https://mefgobpe1.sharepoint.com/:f:/t/DireccindelaOficinadeInfraestructuraTecnolgica/IgDtI1itSj1MRIe9w_PuV_8qAWxI3nhcWFemRLD2qjgXkco?e=DCylEI | AH11: NO | AI11: =IFERROR(IF(AH11="SI",VLOOKUP(A11,$C$4:$AL$151,15,FALSE),"-"),"Sin tramite") -> - | AJ11: =IFERROR(IF(AH11="SI",VLOOKUP(A11,$C$4:$AL$151,7,FALSE),"-"),"Sin HR") -> - | AK11: =IF(AH11="SI",IFERROR(IF(VLOOKUP(A11,$C$4:$AL$151,25,FALSE)="","Sin registro",VLOOKUP(A11,$C$4:$AL$151,25,FALSE)),"Sin registro"),"-") -> - | AL11: =IF(AH11="SI",IFERROR(IF(VLOOKUP(A11,$C$4:$AL$151,26,FALSE)="","Sin registro",VLOOKUP(A11,$C$4:$AL$151,26,FALSE)),"Sin registro"),"-") -> -
A12: REQ-2026-0009 | B12: =IF(OR(Q12="Desistido",Q12="No corresponde Atención OGTI",Q12="Para reformulación",Q12="Paralizado",Q12="-",Z12="Renovado",AND(AH12="NO",Z12="Culminado")),"NO","SI") -> SI | C12: - | D12: NO | E12: Contratación Directa | F12: Nuevo requerimiento | G12: Servicios | H12: Servicio de suscripción de licencias de software para el desarrollo de aplicaciones empresariales de bajo código (low-code) | I12: 040460-2026 | J12: Power Apps Premium | K12: Jefatura OIT | L12: José Romucho Sotelo | M12: Ronald Yrupailla Diaz | N12: Oficina de Sistemas de Información | O12: 1899.16 | P12: 46073 | Q12: Ejecutado | R12: - | S12: - | T12: =IFERROR(IF(OR(Q12="Ejecutado",Q12="No corresponde atención OGTI",Q12="Desistido",Q12="-",Q12="Para reformulación"),"-",IF(OR(S12="-",S12=""),"Falta fecha_estado",NETWORKDAYS(S12,TODAY(),{"02/04/2026";"03/04/2026";"30/06/2026"}))),"-") -> - | U12: Orden de Servicio | V12: 0001453-2026 | W12: 46101 | X12: SEIDOR TECHNOLOGIES PERU S.A.C. | Y12: José Romucho Sotelo | Z12: =IFERROR(IF(Q12="-","-",IF(Q12="Proceso de implementación/Activación/Entrega","Proceso de implementación/Activación/Entrega",IF(OR(Q12="Desistido",Q12="No corresponde atención OGTI",Q12="Para reformulación"),Q12,IF(AND(Q12="Ejecutado",AA12="No aplica",AB12="No Aplica"),"Culminado",IF(Q12="Ejecutado",IF(AND(AC12="-",G12="Bienes"),"Culminado",IF(AC12="-","Falta informacion",IF(AND(AB12-TODAY()>=0,AB12-TODAY()<=90),"Vigente_por vencer",IF(AND(AH12<>"SI",AB12<TODAY()),"Culminado",IF(AND(AH12="SI",AB12<TODAY(),OR(AK12="Sin Registro",AL12="Sin Registro")),"Vencido",IF(AND(AH12="SI",AB12<TODAY(),AK12>AA12,AL12>AB12),"Renovado","Vigente")))))),"En tramite"))))),"-") -> Vigente | AA12: 46106 | AB12: 46470 | AC12: =IFERROR(IF(OR(AA12="-",AA12="",AB12="-",AB12=""),"-",CONCATENATE('Seguimiento OIT'!AB12-'Seguimiento OIT'!AA12+1," dias")),"-") -> 365 dias | AD12: =IFERROR(IF(Z12="Vencido",(TODAY()-AB12)+1,"-"),"-") -> - | AE12: - | AF12: Conformidad HR 072066-2026 | AG12: https://mefgobpe1.sharepoint.com/:f:/t/DireccindelaOficinadeInfraestructuraTecnolgica/IgDtI1itSj1MRIe9w_PuV_8qAWxI3nhcWFemRLD2qjgXkco?e=DCylEI | AH12: NO | AI12: =IFERROR(IF(AH12="SI",VLOOKUP(A12,$C$4:$AL$151,15,FALSE),"-"),"Sin tramite") -> - | AJ12: =IFERROR(IF(AH12="SI",VLOOKUP(A12,$C$4:$AL$151,7,FALSE),"-"),"Sin HR") -> - | AK12: =IF(AH12="SI",IFERROR(IF(VLOOKUP(A12,$C$4:$AL$151,25,FALSE)="","Sin registro",VLOOKUP(A12,$C$4:$AL$151,25,FALSE)),"Sin registro"),"-") -> - | AL12: =IF(AH12="SI",IFERROR(IF(VLOOKUP(A12,$C$4:$AL$151,26,FALSE)="","Sin registro",VLOOKUP(A12,$C$4:$AL$151,26,FALSE)),"Sin registro"),"-") -> -
A13: REQ-2026-0010 | B13: =IF(OR(Q13="Desistido",Q13="No corresponde Atención OGTI",Q13="Para reformulación",Q13="Paralizado",Q13="-",Z13="Renovado",AND(AH13="NO",Z13="Culminado")),"NO","SI") -> NO | C13: - | D13: NO | E13: Contratación Directa | F13: Nuevo requerimiento | G13: Bienes | H13: Adquisición de equipamiento tecnológico para la producción y difusión de contenidos de la Oficina de Comunicaciones | I13: *089135-2026 (Requerimiento) *085712-2026- 005955-2026 (Apoyo presupuestal) | J13: *Discos solidos externos (1 TB y 2TB) *Telepromter *Tablet *Bateria Recargable *Equipo de transmision en vivo *Transmisor de video inalambrico *Tripode con sujetador de movil | K13: Soporte Tecnico | L13: Napoleon Alva Vasquez | M13: Ronald Yrupailla Diaz | N13: Oficina de Comunicaciones | O13: 33330.5 | P13: 46133 | Q13: Ejecutado | R13: - | S13: - | T13: =IFERROR(IF(OR(Q13="Ejecutado",Q13="No corresponde atención OGTI",Q13="Desistido",Q13="-",Q13="Para reformulación"),"-",IF(OR(S13="-",S13=""),"Falta fecha_estado",NETWORKDAYS(S13,TODAY(),{"02/04/2026";"03/04/2026";"30/06/2026"}))),"-") -> - | U13: Orden de Compra | V13: 0000164-2026 | W13: 46167 | X13: CUY TECHNOLOGIES E.I.R.L. | Y13: Napoleon Alva Vasquez | Z13: =IFERROR(IF(Q13="-","-",IF(Q13="Proceso de implementación/Activación/Entrega","Proceso de implementación/Activación/Entrega",IF(OR(Q13="Desistido",Q13="No corresponde atención OGTI",Q13="Para reformulación"),Q13,IF(AND(Q13="Ejecutado",AA13="No aplica",AB13="No Aplica"),"Culminado",IF(Q13="Ejecutado",IF(AND(AC13="-",G13="Bienes"),"Culminado",IF(AC13="-","Falta informacion",IF(AND(AB13-TODAY()>=0,AB13-TODAY()<=90),"Vigente_por vencer",IF(AND(AH13<>"SI",AB13<TODAY()),"Culminado",IF(AND(AH13="SI",AB13<TODAY(),OR(AK13="Sin Registro",AL13="Sin Registro")),"Vencido",IF(AND(AH13="SI",AB13<TODAY(),AK13>AA13,AL13>AB13),"Renovado","Vigente")))))),"En tramite"))))),"-") -> Culminado | AA13: - | AB13: - | AC13: =IFERROR(IF(OR(AA13="-",AA13="",AB13="-",AB13=""),"-",CONCATENATE('Seguimiento OIT'!AB13-'Seguimiento OIT'!AA13+1," dias")),"-") -> - | AD13: =IFERROR(IF(Z13="Vencido",(TODAY()-AB13)+1,"-"),"-") -> - | AE13: - | AF13: Conformidad 120798-2026 / 120456-2026 | AG13: https://mefgobpe1.sharepoint.com/:f:/t/DireccindelaOficinadeInfraestructuraTecnolgica/IgC1sKmCnD2OR6nwjjoR-5QzAWuoyeFD46P5CnRUqQofQSM?e=fKqH5P | AH13: NO | AI13: =IFERROR(IF(AH13="SI",VLOOKUP(A13,$C$4:$AL$151,15,FALSE),"-"),"Sin tramite") -> - | AJ13: =IFERROR(IF(AH13="SI",VLOOKUP(A13,$C$4:$AL$151,7,FALSE),"-"),"Sin HR") -> - | AK13: =IF(AH13="SI",IFERROR(IF(VLOOKUP(A13,$C$4:$AL$151,25,FALSE)="","Sin registro",VLOOKUP(A13,$C$4:$AL$151,25,FALSE)),"Sin registro"),"-") -> - | AL13: =IF(AH13="SI",IFERROR(IF(VLOOKUP(A13,$C$4:$AL$151,26,FALSE)="","Sin registro",VLOOKUP(A13,$C$4:$AL$151,26,FALSE)),"Sin registro"),"-") -> -
A14: REQ-2026-0011 | B14: =IF(OR(Q14="Desistido",Q14="No corresponde Atención OGTI",Q14="Para reformulación",Q14="Paralizado",Q14="-",Z14="Renovado",AND(AH14="NO",Z14="Culminado")),"NO","SI") -> NO | C14: - | D14: NO | E14: Contratación Directa | F14: Nuevo requerimiento | G14: Bienes | H14: Adquisición de equipos de cómputo (CPU y Monitor) para la Oficina de Comunicaciones del Ministerio de Economía y Finanzas | I14: 052742-2026 | J14: *02 Workstation *02 Monitores | K14: Soporte Tecnico | L14: Napoleon Alva Vasquez | M14: Ronald Yrupailla Diaz | N14: Oficina de Comunicaciones | O14: 33211.05 | P14: 46090 | Q14: Ejecutado | R14: - | S14: - | T14: =IFERROR(IF(OR(Q14="Ejecutado",Q14="No corresponde atención OGTI",Q14="Desistido",Q14="-",Q14="Para reformulación"),"-",IF(OR(S14="-",S14=""),"Falta fecha_estado",NETWORKDAYS(S14,TODAY(),{"02/04/2026";"03/04/2026";"30/06/2026"}))),"-") -> - | U14: Orden de Compra | V14: 0000143-2026 | W14: 46148 | X14: COMPU-SISTEMAS DEL PERU SAC | Y14: Napoleon Alva Vasquez | Z14: =IFERROR(IF(Q14="-","-",IF(Q14="Proceso de implementación/Activación/Entrega","Proceso de implementación/Activación/Entrega",IF(OR(Q14="Desistido",Q14="No corresponde atención OGTI",Q14="Para reformulación"),Q14,IF(AND(Q14="Ejecutado",AA14="No aplica",AB14="No Aplica"),"Culminado",IF(Q14="Ejecutado",IF(AND(AC14="-",G14="Bienes"),"Culminado",IF(AC14="-","Falta informacion",IF(AND(AB14-TODAY()>=0,AB14-TODAY()<=90),"Vigente_por vencer",IF(AND(AH14<>"SI",AB14<TODAY()),"Culminado",IF(AND(AH14="SI",AB14<TODAY(),OR(AK14="Sin Registro",AL14="Sin Registro")),"Vencido",IF(AND(AH14="SI",AB14<TODAY(),AK14>AA14,AL14>AB14),"Renovado","Vigente")))))),"En tramite"))))),"-") -> Culminado | AA14: - | AB14: - | AC14: =IFERROR(IF(OR(AA14="-",AA14="",AB14="-",AB14=""),"-",CONCATENATE('Seguimiento OIT'!AB14-'Seguimiento OIT'!AA14+1," dias")),"-") -> - | AD14: =IFERROR(IF(Z14="Vencido",(TODAY()-AB14)+1,"-"),"-") -> - | AE14: - | AF14: Conformidad 113245-2026 | AG14: https://mefgobpe1.sharepoint.com/:f:/t/DireccindelaOficinadeInfraestructuraTecnolgica/IgA5G0WmVxohTqP5MQbMskHSAWM6M_Nigc_QT61A2izummk?e=2mwTcX | AH14: NO | AI14: =IFERROR(IF(AH14="SI",VLOOKUP(A14,$C$4:$AL$151,15,FALSE),"-"),"Sin tramite") -> - | AJ14: =IFERROR(IF(AH14="SI",VLOOKUP(A14,$C$4:$AL$151,7,FALSE),"-"),"Sin HR") -> - | AK14: =IF(AH14="SI",IFERROR(IF(VLOOKUP(A14,$C$4:$AL$151,25,FALSE)="","Sin registro",VLOOKUP(A14,$C$4:$AL$151,25,FALSE)),"Sin registro"),"-") -> - | AL14: =IF(AH14="SI",IFERROR(IF(VLOOKUP(A14,$C$4:$AL$151,26,FALSE)="","Sin registro",VLOOKUP(A14,$C$4:$AL$151,26,FALSE)),"Sin registro"),"-") -> -
A15: REQ-2026-0012 | B15: =IF(OR(Q15="Desistido",Q15="No corresponde Atención OGTI",Q15="Para reformulación",Q15="Paralizado",Q15="-",Z15="Renovado",AND(AH15="NO",Z15="Culminado")),"NO","SI") -> SI | C15: - | D15: NO | E15: Contratación Directa | F15: Renovación | G15: Servicios | H15: Servicio de suscripción de licencias de software para la gestión de videoconferencias (Modo Cloud) de la Oficina General de Recursos Humanos del Ministerio de Economía y Finanzas | I15: *101707-2026 (Requerimiento) *088416-202 (Req 01) *097140-2026 (Apoyo presupuestal) | J15: Zoom Business (15 licencias) | K15: Jefatura OIT | L15: José Romucho Sotelo | M15: Ronald Yrupailla Diaz | N15: Oficina General de Recursos Humanos | O15: 13650 | P15: 46153 | Q15: Ejecutado | R15: - | S15: - | T15: =IFERROR(IF(OR(Q15="Ejecutado",Q15="No corresponde atención OGTI",Q15="Desistido",Q15="-",Q15="Para reformulación"),"-",IF(OR(S15="-",S15=""),"Falta fecha_estado",NETWORKDAYS(S15,TODAY(),{"02/04/2026";"03/04/2026";"30/06/2026"}))),"-") -> - | U15: Orden de Servicio | V15: 0002637-2026 | W15: 46163 | X15: ARGACORP S.A.C. | Y15: José Romucho Sotelo | Z15: =IFERROR(IF(Q15="-","-",IF(Q15="Proceso de implementación/Activación/Entrega","Proceso de implementación/Activación/Entrega",IF(OR(Q15="Desistido",Q15="No corresponde atención OGTI",Q15="Para reformulación"),Q15,IF(AND(Q15="Ejecutado",AA15="No aplica",AB15="No Aplica"),"Culminado",IF(Q15="Ejecutado",IF(AND(AC15="-",G15="Bienes"),"Culminado",IF(AC15="-","Falta informacion",IF(AND(AB15-TODAY()>=0,AB15-TODAY()<=90),"Vigente_por vencer",IF(AND(AH15<>"SI",AB15<TODAY()),"Culminado",IF(AND(AH15="SI",AB15<TODAY(),OR(AK15="Sin Registro",AL15="Sin Registro")),"Vencido",IF(AND(AH15="SI",AB15<TODAY(),AK15>AA15,AL15>AB15),"Renovado","Vigente")))))),"En tramite"))))),"-") -> Vigente | AA15: 46167 | AB15: 46531 | AC15: =IFERROR(IF(OR(AA15="-",AA15="",AB15="-",AB15=""),"-",CONCATENATE('Seguimiento OIT'!AB15-'Seguimiento OIT'!AA15+1," dias")),"-") -> 365 dias | AD15: =IFERROR(IF(Z15="Vencido",(TODAY()-AB15)+1,"-"),"-") -> - | AE15: - | AF15: Conformidad 118804-2026 | AG15: https://mefgobpe1.sharepoint.com/:f:/t/DireccindelaOficinadeInfraestructuraTecnolgica/IgBFT23nqG9zQ7rbTFVcZ7QxAYluJ9F4NfR0qxfKpTAXlgY?e=nMW8TE | AH15: NO | AI15: =IFERROR(IF(AH15="SI",VLOOKUP(A15,$C$4:$AL$151,15,FALSE),"-"),"Sin tramite") -> - | AJ15: =IFERROR(IF(AH15="SI",VLOOKUP(A15,$C$4:$AL$151,7,FALSE),"-"),"Sin HR") -> - | AK15: =IF(AH15="SI",IFERROR(IF(VLOOKUP(A15,$C$4:$AL$151,25,FALSE)="","Sin registro",VLOOKUP(A15,$C$4:$AL$151,25,FALSE)),"Sin registro"),"-") -> - | AL15: =IF(AH15="SI",IFERROR(IF(VLOOKUP(A15,$C$4:$AL$151,26,FALSE)="","Sin registro",VLOOKUP(A15,$C$4:$AL$151,26,FALSE)),"Sin registro"),"-") -> -
A16: REQ-2026-0013 | B16: =IF(OR(Q16="Desistido",Q16="No corresponde Atención OGTI",Q16="Para reformulación",Q16="Paralizado",Q16="-",Z16="Renovado",AND(AH16="NO",Z16="Culminado")),"NO","SI") -> NO | C16: - | D16: NO | E16: Contratación Directa | F16: Nuevo requerimiento | G16: Bienes | H16: Adquisición de accesorios informáticos para equipos de cómputo (Lectoras CD/DVD)-OGSU | I16: *114171-2026 (Requerimiento consolidado) *073576-2026 (Requerimiento inicial) *109395-2026 (Apoyo presupuesta) | J16: Lectoras externas de CD/DVD (06 unidades) | K16: Soporte Tecnico | L16: Napoleon Alva Vasquez | M16: Ronald Yrupailla Diaz | N16: Oficina General de Servicios al Usuario | O16: 660 | P16: 46164 | Q16: Ejecutado | R16: - | S16: - | T16: =IFERROR(IF(OR(Q16="Ejecutado",Q16="No corresponde atención OGTI",Q16="Desistido",Q16="-",Q16="Para reformulación"),"-",IF(OR(S16="-",S16=""),"Falta fecha_estado",NETWORKDAYS(S16,TODAY(),{"02/04/2026";"03/04/2026";"30/06/2026"}))),"-") -> - | U16: Orden de Compra | V16: 0000182-2026 | W16: 46176 | X16: CUY TECHNOLOGIES E.I.R.L. | Y16: Napoleon Alva Vasquez | Z16: =IFERROR(IF(Q16="-","-",IF(Q16="Proceso de implementación/Activación/Entrega","Proceso de implementación/Activación/Entrega",IF(OR(Q16="Desistido",Q16="No corresponde atención OGTI",Q16="Para reformulación"),Q16,IF(AND(Q16="Ejecutado",AA16="No aplica",AB16="No Aplica"),"Culminado",IF(Q16="Ejecutado",IF(AND(AC16="-",G16="Bienes"),"Culminado",IF(AC16="-","Falta informacion",IF(AND(AB16-TODAY()>=0,AB16-TODAY()<=90),"Vigente_por vencer",IF(AND(AH16<>"SI",AB16<TODAY()),"Culminado",IF(AND(AH16="SI",AB16<TODAY(),OR(AK16="Sin Registro",AL16="Sin Registro")),"Vencido",IF(AND(AH16="SI",AB16<TODAY(),AK16>AA16,AL16>AB16),"Renovado","Vigente")))))),"En tramite"))))),"-") -> Culminado | AA16: - | AB16: - | AC16: =IFERROR(IF(OR(AA16="-",AA16="",AB16="-",AB16=""),"-",CONCATENATE('Seguimiento OIT'!AB16-'Seguimiento OIT'!AA16+1," dias")),"-") -> - | AD16: =IFERROR(IF(Z16="Vencido",(TODAY()-AB16)+1,"-"),"-") -> - | AE16: - | AF16: Conformidad 125911-2026 | AG16: https://mefgobpe1.sharepoint.com/:f:/t/DireccindelaOficinadeInfraestructuraTecnolgica/IgBggS-oH5JqTr_6GWypG4b4ATKxqfyCVeq7C0aBSIKTF4c?e=LBGJEY | AH16: NO | AI16: =IFERROR(IF(AH16="SI",VLOOKUP(A16,$C$4:$AL$151,15,FALSE),"-"),"Sin tramite") -> - | AJ16: =IFERROR(IF(AH16="SI",VLOOKUP(A16,$C$4:$AL$151,7,FALSE),"-"),"Sin HR") -> - | AK16: =IF(AH16="SI",IFERROR(IF(VLOOKUP(A16,$C$4:$AL$151,25,FALSE)="","Sin registro",VLOOKUP(A16,$C$4:$AL$151,25,FALSE)),"Sin registro"),"-") -> - | AL16: =IF(AH16="SI",IFERROR(IF(VLOOKUP(A16,$C$4:$AL$151,26,FALSE)="","Sin registro",VLOOKUP(A16,$C$4:$AL$151,26,FALSE)),"Sin registro"),"-") -> -
A17: REQ-2026-0014 | B17: =IF(OR(Q17="Desistido",Q17="No corresponde Atención OGTI",Q17="Para reformulación",Q17="Paralizado",Q17="-",Z17="Renovado",AND(AH17="NO",Z17="Culminado")),"NO","SI") -> NO | C17: - | D17: NO | E17: Contratación Directa | F17: Nuevo requerimiento | G17: Bienes | H17: Adquisición de accesorios informáticos para equipos de cómputo (Lectoras CD/DVD)-Procuradoria | I17: *114171-2026 (Requerimiento consolidado) *Correo (Requerimiento inicial) | J17: Lectoras externas de CD/DVD (03 unidades) | K17: Soporte Tecnico | L17: Napoleon Alva Vasquez | M17: Ronald Yrupailla Diaz | N17: Procuraduría Pública Especializada en Materia Hacendaria | O17: 330 | P17: 46164 | Q17: Ejecutado | R17: - | S17: - | T17: =IFERROR(IF(OR(Q17="Ejecutado",Q17="No corresponde atención OGTI",Q17="Desistido",Q17="-",Q17="Para reformulación"),"-",IF(OR(S17="-",S17=""),"Falta fecha_estado",NETWORKDAYS(S17,TODAY(),{"02/04/2026";"03/04/2026";"30/06/2026"}))),"-") -> - | U17: Orden de Compra | V17: 0000182-2026 | W17: 46176 | X17: CUY TECHNOLOGIES E.I.R.L. | Y17: Napoleon Alva Vasquez | Z17: =IFERROR(IF(Q17="-","-",IF(Q17="Proceso de implementación/Activación/Entrega","Proceso de implementación/Activación/Entrega",IF(OR(Q17="Desistido",Q17="No corresponde atención OGTI",Q17="Para reformulación"),Q17,IF(AND(Q17="Ejecutado",AA17="No aplica",AB17="No Aplica"),"Culminado",IF(Q17="Ejecutado",IF(AND(AC17="-",G17="Bienes"),"Culminado",IF(AC17="-","Falta informacion",IF(AND(AB17-TODAY()>=0,AB17-TODAY()<=90),"Vigente_por vencer",IF(AND(AH17<>"SI",AB17<TODAY()),"Culminado",IF(AND(AH17="SI",AB17<TODAY(),OR(AK17="Sin Registro",AL17="Sin Registro")),"Vencido",IF(AND(AH17="SI",AB17<TODAY(),AK17>AA17,AL17>AB17),"Renovado","Vigente")))))),"En tramite"))))),"-") -> Culminado | AA17: - | AB17: - | AC17: =IFERROR(IF(OR(AA17="-",AA17="",AB17="-",AB17=""),"-",CONCATENATE('Seguimiento OIT'!AB17-'Seguimiento OIT'!AA17+1," dias")),"-") -> - | AD17: =IFERROR(IF(Z17="Vencido",(TODAY()-AB17)+1,"-"),"-") -> - | AE17: - | AF17: Conformidad 125911-2026 | AG17: https://mefgobpe1.sharepoint.com/:f:/t/DireccindelaOficinadeInfraestructuraTecnolgica/IgAhsups6_SGQojMLYgdHk-0AXwoAEv3n-GpPgZzS4F96cQ?e=SUEvKN | AH17: NO | AI17: =IFERROR(IF(AH17="SI",VLOOKUP(A17,$C$4:$AL$151,15,FALSE),"-"),"Sin tramite") -> - | AJ17: =IFERROR(IF(AH17="SI",VLOOKUP(A17,$C$4:$AL$151,7,FALSE),"-"),"Sin HR") -> - | AK17: =IF(AH17="SI",IFERROR(IF(VLOOKUP(A17,$C$4:$AL$151,25,FALSE)="","Sin registro",VLOOKUP(A17,$C$4:$AL$151,25,FALSE)),"Sin registro"),"-") -> - | AL17: =IF(AH17="SI",IFERROR(IF(VLOOKUP(A17,$C$4:$AL$151,26,FALSE)="","Sin registro",VLOOKUP(A17,$C$4:$AL$151,26,FALSE)),"Sin registro"),"-") -> -
A18: REQ-2026-0015 | B18: =IF(OR(Q18="Desistido",Q18="No corresponde Atención OGTI",Q18="Para reformulación",Q18="Paralizado",Q18="-",Z18="Renovado",AND(AH18="NO",Z18="Culminado")),"NO","SI") -> NO | C18: - | D18: NO | E18: Contratación Directa | F18: Nuevo requerimiento | G18: Bienes | H18: Adquisición de accesorios informáticos para equipos de cómputo (Adaptador HDMI-VGA y Cable de seguridad Laptop)-DEFCON | I18: *114171-2026 (Requerimiento consolidado) *092014-2026 / 082489-2026 (Requerimiento inicial) | J18: *Adaptador HDMI a VGA *Cable de seguridad para laptop | K18: Soporte Tecnico | L18: Napoleon Alva Vasquez | M18: Ronald Yrupailla Diaz | N18: Procuraduría Pública Especializada en Materia Hacendaria | O18: 1610 | P18: 46164 | Q18: Ejecutado | R18: - | S18: - | T18: =IFERROR(IF(OR(Q18="Ejecutado",Q18="No corresponde atención OGTI",Q18="Desistido",Q18="-",Q18="Para reformulación"),"-",IF(OR(S18="-",S18=""),"Falta fecha_estado",NETWORKDAYS(S18,TODAY(),{"02/04/2026";"03/04/2026";"30/06/2026"}))),"-") -> - | U18: Orden de Compra | V18: 0000182-2026 | W18: 46176 | X18: CUY TECHNOLOGIES E.I.R.L. | Y18: Napoleon Alva Vasquez | Z18: =IFERROR(IF(Q18="-","-",IF(Q18="Proceso de implementación/Activación/Entrega","Proceso de implementación/Activación/Entrega",IF(OR(Q18="Desistido",Q18="No corresponde atención OGTI",Q18="Para reformulación"),Q18,IF(AND(Q18="Ejecutado",AA18="No aplica",AB18="No Aplica"),"Culminado",IF(Q18="Ejecutado",IF(AND(AC18="-",G18="Bienes"),"Culminado",IF(AC18="-","Falta informacion",IF(AND(AB18-TODAY()>=0,AB18-TODAY()<=90),"Vigente_por vencer",IF(AND(AH18<>"SI",AB18<TODAY()),"Culminado",IF(AND(AH18="SI",AB18<TODAY(),OR(AK18="Sin Registro",AL18="Sin Registro")),"Vencido",IF(AND(AH18="SI",AB18<TODAY(),AK18>AA18,AL18>AB18),"Renovado","Vigente")))))),"En tramite"))))),"-") -> Culminado | AA18: - | AB18: - | AC18: =IFERROR(IF(OR(AA18="-",AA18="",AB18="-",AB18=""),"-",CONCATENATE('Seguimiento OIT'!AB18-'Seguimiento OIT'!AA18+1," dias")),"-") -> - | AD18: =IFERROR(IF(Z18="Vencido",(TODAY()-AB18)+1,"-"),"-") -> - | AE18: - | AF18: Conformidad 125911-2026 | AG18: https://mefgobpe1.sharepoint.com/:f:/t/DireccindelaOficinadeInfraestructuraTecnolgica/IgCll127HQEpSImNYotDU9X-AVijdG8ZVg50_SyeasEmpiA?e=acIxyJ | AH18: NO | AI18: =IFERROR(IF(AH18="SI",VLOOKUP(A18,$C$4:$AL$151,15,FALSE),"-"),"Sin tramite") -> - | AJ18: =IFERROR(IF(AH18="SI",VLOOKUP(A18,$C$4:$AL$151,7,FALSE),"-"),"Sin HR") -> - | AK18: =IF(AH18="SI",IFERROR(IF(VLOOKUP(A18,$C$4:$AL$151,25,FALSE)="","Sin registro",VLOOKUP(A18,$C$4:$AL$151,25,FALSE)),"Sin registro"),"-") -> - | AL18: =IF(AH18="SI",IFERROR(IF(VLOOKUP(A18,$C$4:$AL$151,26,FALSE)="","Sin registro",VLOOKUP(A18,$C$4:$AL$151,26,FALSE)),"Sin registro"),"-") -> -
A19: REQ-2026-0016 | B19: =IF(OR(Q19="Desistido",Q19="No corresponde Atención OGTI",Q19="Para reformulación",Q19="Paralizado",Q19="-",Z19="Renovado",AND(AH19="NO",Z19="Culminado")),"NO","SI") -> SI | C19: - | D19: NO | E19: Contratación Directa | F19: Renovación | G19: Servicios | H19: Servicio de Suscripción de Software de Gestión de Proyectos de la marca Microsoft | I19: 080309-2026 | J19: Planner y Project Plan 3 (23 unidades) | K19: Jefatura OIT | L19: José Romucho Sotelo | M19: Ronald Yrupailla Diaz | N19: Oficina General de Tecnologías de la Información | O19: 43165 | P19: 46122 | Q19: Ejecutado | R19: - | S19: - | T19: =IFERROR(IF(OR(Q19="Ejecutado",Q19="No corresponde atención OGTI",Q19="Desistido",Q19="-",Q19="Para reformulación"),"-",IF(OR(S19="-",S19=""),"Falta fecha_estado",NETWORKDAYS(S19,TODAY(),{"02/04/2026";"03/04/2026";"30/06/2026"}))),"-") -> - | U19: Orden de Servicio | V19: 0002327-2026 | W19: 46147 | X19: DAILY TECHNOLOGY S.A.C | Y19: José Romucho Sotelo | Z19: =IFERROR(IF(Q19="-","-",IF(Q19="Proceso de implementación/Activación/Entrega","Proceso de implementación/Activación/Entrega",IF(OR(Q19="Desistido",Q19="No corresponde atención OGTI",Q19="Para reformulación"),Q19,IF(AND(Q19="Ejecutado",AA19="No aplica",AB19="No Aplica"),"Culminado",IF(Q19="Ejecutado",IF(AND(AC19="-",G19="Bienes"),"Culminado",IF(AC19="-","Falta informacion",IF(AND(AB19-TODAY()>=0,AB19-TODAY()<=90),"Vigente_por vencer",IF(AND(AH19<>"SI",AB19<TODAY()),"Culminado",IF(AND(AH19="SI",AB19<TODAY(),OR(AK19="Sin Registro",AL19="Sin Registro")),"Vencido",IF(AND(AH19="SI",AB19<TODAY(),AK19>AA19,AL19>AB19),"Renovado","Vigente")))))),"En tramite"))))),"-") -> Vigente | AA19: 46163 | AB19: 46527 | AC19: =IFERROR(IF(OR(AA19="-",AA19="",AB19="-",AB19=""),"-",CONCATENATE('Seguimiento OIT'!AB19-'Seguimiento OIT'!AA19+1," dias")),"-") -> 365 dias | AD19: =IFERROR(IF(Z19="Vencido",(TODAY()-AB19)+1,"-"),"-") -> - | AE19: - | AF19: *Conformidad 114042-2026 *Reduccion de o.s 114497-2026 | AG19: https://mefgobpe1.sharepoint.com/:f:/t/DireccindelaOficinadeInfraestructuraTecnolgica/IgA_ThXieabKQYWhIq9N88JYAUdCaTsOhspNLFXZ1xVx_XQ?e=6VmMxh | AH19: NO | AI19: =IFERROR(IF(AH19="SI",VLOOKUP(A19,$C$4:$AL$151,15,FALSE),"-"),"Sin tramite") -> - | AJ19: =IFERROR(IF(AH19="SI",VLOOKUP(A19,$C$4:$AL$151,7,FALSE),"-"),"Sin HR") -> - | AK19: =IF(AH19="SI",IFERROR(IF(VLOOKUP(A19,$C$4:$AL$151,25,FALSE)="","Sin registro",VLOOKUP(A19,$C$4:$AL$151,25,FALSE)),"Sin registro"),"-") -> - | AL19: =IF(AH19="SI",IFERROR(IF(VLOOKUP(A19,$C$4:$AL$151,26,FALSE)="","Sin registro",VLOOKUP(A19,$C$4:$AL$151,26,FALSE)),"Sin registro"),"-") -> -
A20: REQ-2026-0017 | B20: =IF(OR(Q20="Desistido",Q20="No corresponde Atención OGTI",Q20="Para reformulación",Q20="Paralizado",Q20="-",Z20="Renovado",AND(AH20="NO",Z20="Culminado")),"NO","SI") -> SI | C20: - | D20: NO | E20: Contratación Directa | F20: Nuevo requerimiento | G20: Servicios | H20: Servicio de notificaciones masivas para mensajería empresarial (WhatsApp) a través de la plataforma INFOBIP | I20: 015282-2026 | J20: *34,000 creditos *03 Agentes *5000 sesiones x mes | K20: Jefatura OIT | L20: José Romucho Sotelo | M20: Ronald Yrupailla Diaz | N20: Oficina de Sistemas de Información | O20: 43890 | P20: 46049 | Q20: Ejecutado | R20: - | S20: - | T20: =IFERROR(IF(OR(Q20="Ejecutado",Q20="No corresponde atención OGTI",Q20="Desistido",Q20="-",Q20="Para reformulación"),"-",IF(OR(S20="-",S20=""),"Falta fecha_estado",NETWORKDAYS(S20,TODAY(),{"02/04/2026";"03/04/2026";"30/06/2026"}))),"-") -> - | U20: Orden de Servicio | V20: 0001386-2026 | W20: 46097 | X20: ENTEL PERU S.A. | Y20: José Romucho Sotelo | Z20: =IFERROR(IF(Q20="-","-",IF(Q20="Proceso de implementación/Activación/Entrega","Proceso de implementación/Activación/Entrega",IF(OR(Q20="Desistido",Q20="No corresponde atención OGTI",Q20="Para reformulación"),Q20,IF(AND(Q20="Ejecutado",AA20="No aplica",AB20="No Aplica"),"Culminado",IF(Q20="Ejecutado",IF(AND(AC20="-",G20="Bienes"),"Culminado",IF(AC20="-","Falta informacion",IF(AND(AB20-TODAY()>=0,AB20-TODAY()<=90),"Vigente_por vencer",IF(AND(AH20<>"SI",AB20<TODAY()),"Culminado",IF(AND(AH20="SI",AB20<TODAY(),OR(AK20="Sin Registro",AL20="Sin Registro")),"Vencido",IF(AND(AH20="SI",AB20<TODAY(),AK20>AA20,AL20>AB20),"Renovado","Vigente")))))),"En tramite"))))),"-") -> Vigente | AA20: 46150 | AB20: 46334 | AC20: =IFERROR(IF(OR(AA20="-",AA20="",AB20="-",AB20=""),"-",CONCATENATE('Seguimiento OIT'!AB20-'Seguimiento OIT'!AA20+1," dias")),"-") -> 185 dias | AD20: =IFERROR(IF(Z20="Vencido",(TODAY()-AB20)+1,"-"),"-") -> - | AE20: - | AF20: *Ampliacion de plazo 101774-2026 / 101763-2026 *Conformidad 110185-2026 | AG20: https://mefgobpe1.sharepoint.com/:f:/t/DireccindelaOficinadeInfraestructuraTecnolgica/IgAJ7qpoO04-RKLsaYI_TPCaAVnLB3BfeTI4TPceZmZC55c?e=sVYOpK | AH20: NO | AI20: =IFERROR(IF(AH20="SI",VLOOKUP(A20,$C$4:$AL$151,15,FALSE),"-"),"Sin tramite") -> - | AJ20: =IFERROR(IF(AH20="SI",VLOOKUP(A20,$C$4:$AL$151,7,FALSE),"-"),"Sin HR") -> - | AK20: =IF(AH20="SI",IFERROR(IF(VLOOKUP(A20,$C$4:$AL$151,25,FALSE)="","Sin registro",VLOOKUP(A20,$C$4:$AL$151,25,FALSE)),"Sin registro"),"-") -> - | AL20: =IF(AH20="SI",IFERROR(IF(VLOOKUP(A20,$C$4:$AL$151,26,FALSE)="","Sin registro",VLOOKUP(A20,$C$4:$AL$151,26,FALSE)),"Sin registro"),"-") -> -
A21: REQ-2026-0018 | B21: =IF(OR(Q21="Desistido",Q21="No corresponde Atención OGTI",Q21="Para reformulación",Q21="Paralizado",Q21="-",Z21="Renovado",AND(AH21="NO",Z21="Culminado")),"NO","SI") -> SI | C21: - | D21: NO | E21: Contratación Directa | F21: Nuevo requerimiento | G21: Servicios | H21: Certificados digitales de persona jurídica - RENIEC | I21: 081249-2026 | J21: 1500 Certificados digitales | K21: Soporte Tecnico | L21: José Romucho Sotelo | M21: Ronald Yrupailla Diaz | N21: Oficina de Infraestructura Tecnológica | O21: 12150 | P21: 46122 | Q21: Ejecutado | R21: - | S21: - | T21: =IFERROR(IF(OR(Q21="Ejecutado",Q21="No corresponde atención OGTI",Q21="Desistido",Q21="-",Q21="Para reformulación"),"-",IF(OR(S21="-",S21=""),"Falta fecha_estado",NETWORKDAYS(S21,TODAY(),{"02/04/2026";"03/04/2026";"30/06/2026"}))),"-") -> - | U21: Nota de Compromiso | V21: 0345-2026-EF | W21: 46128 | X21: RENIEC | Y21: José Romucho Sotelo | Z21: =IFERROR(IF(Q21="-","-",IF(Q21="Proceso de implementación/Activación/Entrega","Proceso de implementación/Activación/Entrega",IF(OR(Q21="Desistido",Q21="No corresponde atención OGTI",Q21="Para reformulación"),Q21,IF(AND(Q21="Ejecutado",AA21="No aplica",AB21="No Aplica"),"Culminado",IF(Q21="Ejecutado",IF(AND(AC21="-",G21="Bienes"),"Culminado",IF(AC21="-","Falta informacion",IF(AND(AB21-TODAY()>=0,AB21-TODAY()<=90),"Vigente_por vencer",IF(AND(AH21<>"SI",AB21<TODAY()),"Culminado",IF(AND(AH21="SI",AB21<TODAY(),OR(AK21="Sin Registro",AL21="Sin Registro")),"Vencido",IF(AND(AH21="SI",AB21<TODAY(),AK21>AA21,AL21>AB21),"Renovado","Vigente")))))),"En tramite"))))),"-") -> Vigente_por vencer | AA21: 46113 | AB21: 46265 | AC21: =IFERROR(IF(OR(AA21="-",AA21="",AB21="-",AB21=""),"-",CONCATENATE('Seguimiento OIT'!AB21-'Seguimiento OIT'!AA21+1," dias")),"-") -> 153 dias | AD21: =IFERROR(IF(Z21="Vencido",(TODAY()-AB21)+1,"-"),"-") -> - | AE21: - | AF21: - | AG21: https://mefgobpe1.sharepoint.com/:f:/t/DireccindelaOficinadeInfraestructuraTecnolgica/IgA9cJfXxPsWSrNqD9HaRbozAaXWixz8fwTopb-CgIW66Dg?e=QYD4wl | AH21: NO | AI21: =IFERROR(IF(AH21="SI",VLOOKUP(A21,$C$4:$AL$151,15,FALSE),"-"),"Sin tramite") -> - | AJ21: =IFERROR(IF(AH21="SI",VLOOKUP(A21,$C$4:$AL$151,7,FALSE),"-"),"Sin HR") -> - | AK21: =IF(AH21="SI",IFERROR(IF(VLOOKUP(A21,$C$4:$AL$151,25,FALSE)="","Sin registro",VLOOKUP(A21,$C$4:$AL$151,25,FALSE)),"Sin registro"),"-") -> - | AL21: =IF(AH21="SI",IFERROR(IF(VLOOKUP(A21,$C$4:$AL$151,26,FALSE)="","Sin registro",VLOOKUP(A21,$C$4:$AL$151,26,FALSE)),"Sin registro"),"-") -> -
A22: REQ-2026-0019 | B22: =IF(OR(Q22="Desistido",Q22="No corresponde Atención OGTI",Q22="Para reformulación",Q22="Paralizado",Q22="-",Z22="Renovado",AND(AH22="NO",Z22="Culminado")),"NO","SI") -> NO | C22: - | D22: NO | E22: Contratación Directa | F22: Nuevo requerimiento | G22: Bienes | H22: Adquisición de impresora multifuncional laser a color | I22: 085801-2026 | J22: Impresora a color | K22: Soporte Tecnico | L22: Napoleon Alva Vasquez | M22: Ronald Yrupailla Diaz | N22: Secretaría General | O22: 26724.01 | P22: 46129 | Q22: Ejecutado | R22: - | S22: - | T22: =IFERROR(IF(OR(Q22="Ejecutado",Q22="No corresponde atención OGTI",Q22="Desistido",Q22="-",Q22="Para reformulación"),"-",IF(OR(S22="-",S22=""),"Falta fecha_estado",NETWORKDAYS(S22,TODAY(),{"02/04/2026";"03/04/2026";"30/06/2026"}))),"-") -> - | U22: Orden de Compra | V22: 0000137-2026 | W22: 46140 | X22: TEAMWORK CONSULTING & GENERAL SERVICES S.A.C. | Y22: Napoleon Alva Vasquez | Z22: =IFERROR(IF(Q22="-","-",IF(Q22="Proceso de implementación/Activación/Entrega","Proceso de implementación/Activación/Entrega",IF(OR(Q22="Desistido",Q22="No corresponde atención OGTI",Q22="Para reformulación"),Q22,IF(AND(Q22="Ejecutado",AA22="No aplica",AB22="No Aplica"),"Culminado",IF(Q22="Ejecutado",IF(AND(AC22="-",G22="Bienes"),"Culminado",IF(AC22="-","Falta informacion",IF(AND(AB22-TODAY()>=0,AB22-TODAY()<=90),"Vigente_por vencer",IF(AND(AH22<>"SI",AB22<TODAY()),"Culminado",IF(AND(AH22="SI",AB22<TODAY(),OR(AK22="Sin Registro",AL22="Sin Registro")),"Vencido",IF(AND(AH22="SI",AB22<TODAY(),AK22>AA22,AL22>AB22),"Renovado","Vigente")))))),"En tramite"))))),"-") -> Culminado | AA22: - | AB22: - | AC22: =IFERROR(IF(OR(AA22="-",AA22="",AB22="-",AB22=""),"-",CONCATENATE('Seguimiento OIT'!AB22-'Seguimiento OIT'!AA22+1," dias")),"-") -> - | AD22: =IFERROR(IF(Z22="Vencido",(TODAY()-AB22)+1,"-"),"-") -> - | AE22: - | AF22: *Conformidad 099839-2026 *Antecedente 192039-2025 | AG22: https://mefgobpe1.sharepoint.com/:f:/t/DireccindelaOficinadeInfraestructuraTecnolgica/IgC5keBoO6yUTY2pp9YKreusASg9cM4_iBsOqn5zrKc9kHA?e=wC8brs | AH22: NO | AI22: =IFERROR(IF(AH22="SI",VLOOKUP(A22,$C$4:$AL$151,15,FALSE),"-"),"Sin tramite") -> - | AJ22: =IFERROR(IF(AH22="SI",VLOOKUP(A22,$C$4:$AL$151,7,FALSE),"-"),"Sin HR") -> - | AK22: =IF(AH22="SI",IFERROR(IF(VLOOKUP(A22,$C$4:$AL$151,25,FALSE)="","Sin registro",VLOOKUP(A22,$C$4:$AL$151,25,FALSE)),"Sin registro"),"-") -> - | AL22: =IF(AH22="SI",IFERROR(IF(VLOOKUP(A22,$C$4:$AL$151,26,FALSE)="","Sin registro",VLOOKUP(A22,$C$4:$AL$151,26,FALSE)),"Sin registro"),"-") -> -
A23: REQ-2026-0020 | B23: =IF(OR(Q23="Desistido",Q23="No corresponde Atención OGTI",Q23="Para reformulación",Q23="Paralizado",Q23="-",Z23="Renovado",AND(AH23="NO",Z23="Culminado")),"NO","SI") -> NO | C23: - | D23: NO | E23: Contratación Directa | F23: Nuevo requerimiento | G23: Bienes | H23: Adquisición de tótem multimedia para la Oficina de Gestión Documental y Atención al Usuario (OGDAU) | I23: *084299-2026 (Requerimiento) **109395-2026 (Apoyo presupuestal) | J23: Totem Multimedia | K23: Soporte Tecnico | L23: Napoleon Alva Vasquez | M23: Ronald Yrupailla Diaz | N23: Oficina General de Servicios al Usuario | O23: 13865 | P23: 46167 | Q23: Ejecutado | R23: - | S23: - | T23: =IFERROR(IF(OR(Q23="Ejecutado",Q23="No corresponde atención OGTI",Q23="Desistido",Q23="-",Q23="Para reformulación"),"-",IF(OR(S23="-",S23=""),"Falta fecha_estado",NETWORKDAYS(S23,TODAY(),{"02/04/2026";"03/04/2026";"30/06/2026"}))),"-") -> - | U23: Orden de Compra | V23: 0000224-2026 | W23: 46197 | X23: HOLIGRAM E.I.R.L | Y23: Napoleon Alva Vasquez | Z23: =IFERROR(IF(Q23="-","-",IF(Q23="Proceso de implementación/Activación/Entrega","Proceso de implementación/Activación/Entrega",IF(OR(Q23="Desistido",Q23="No corresponde atención OGTI",Q23="Para reformulación"),Q23,IF(AND(Q23="Ejecutado",AA23="No aplica",AB23="No Aplica"),"Culminado",IF(Q23="Ejecutado",IF(AND(AC23="-",G23="Bienes"),"Culminado",IF(AC23="-","Falta informacion",IF(AND(AB23-TODAY()>=0,AB23-TODAY()<=90),"Vigente_por vencer",IF(AND(AH23<>"SI",AB23<TODAY()),"Culminado",IF(AND(AH23="SI",AB23<TODAY(),OR(AK23="Sin Registro",AL23="Sin Registro")),"Vencido",IF(AND(AH23="SI",AB23<TODAY(),AK23>AA23,AL23>AB23),"Renovado","Vigente")))))),"En tramite"))))),"-") -> Culminado | AA23: - | AB23: - | AC23: =IFERROR(IF(OR(AA23="-",AA23="",AB23="-",AB23=""),"-",CONCATENATE('Seguimiento OIT'!AB23-'Seguimiento OIT'!AA23+1," dias")),"-") -> - | AD23: =IFERROR(IF(Z23="Vencido",(TODAY()-AB23)+1,"-"),"-") -> - | AE23: - | AF23: *Conformidad (HR 159104-2026) | AG23: https://mefgobpe1.sharepoint.com/:f:/t/DireccindelaOficinadeInfraestructuraTecnolgica/IgBkEDxQVsnrSZNPX9ZDIeapAZSZtEMhDBEtCdy2R1qrdLs?e=RR4APt | AH23: NO | AI23: =IFERROR(IF(AH23="SI",VLOOKUP(A23,$C$4:$AL$151,15,FALSE),"-"),"Sin tramite") -> - | AJ23: =IFERROR(IF(AH23="SI",VLOOKUP(A23,$C$4:$AL$151,7,FALSE),"-"),"Sin HR") -> - | AK23: =IF(AH23="SI",IFERROR(IF(VLOOKUP(A23,$C$4:$AL$151,25,FALSE)="","Sin registro",VLOOKUP(A23,$C$4:$AL$151,25,FALSE)),"Sin registro"),"-") -> - | AL23: =IF(AH23="SI",IFERROR(IF(VLOOKUP(A23,$C$4:$AL$151,26,FALSE)="","Sin registro",VLOOKUP(A23,$C$4:$AL$151,26,FALSE)),"Sin registro"),"-") -> -
A24: REQ-2026-0021 | B24: =IF(OR(Q24="Desistido",Q24="No corresponde Atención OGTI",Q24="Para reformulación",Q24="Paralizado",Q24="-",Z24="Renovado",AND(AH24="NO",Z24="Culminado")),"NO","SI") -> SI | C24: - | D24: NO | E24: Contratación Directa | F24: Renovación | G24: Servicios | H24: Servicio de alquiler de escáneres de alta Producción para la línea de producción de microformas | I24: 031853-2026 | J24: Alquiler de escáneres de alta Producción | K24: Redes y Comunicaciones | L24: Elliot Hans Lindo Claudet | M24: Elliot Hans Lindo Claudet | N24: Oficina de Infraestructura Tecnológica | O24: 43992 | Q24: Ejecutado | R24: - | S24: - | T24: =IFERROR(IF(OR(Q24="Ejecutado",Q24="No corresponde atención OGTI",Q24="Desistido",Q24="-",Q24="Para reformulación"),"-",IF(OR(S24="-",S24=""),"Falta fecha_estado",NETWORKDAYS(S24,TODAY(),{"02/04/2026";"03/04/2026";"30/06/2026"}))),"-") -> - | U24: Contrato | V24: 003-2026-EF/43.03/CM | W24: 46086 | X24: GRUPO VENTURA PERU S.A.C. | Y24: Elliot Hans Lindo Claudet | Z24: =IFERROR(IF(Q24="-","-",IF(Q24="Proceso de implementación/Activación/Entrega","Proceso de implementación/Activación/Entrega",IF(OR(Q24="Desistido",Q24="No corresponde atención OGTI",Q24="Para reformulación"),Q24,IF(AND(Q24="Ejecutado",AA24="No aplica",AB24="No Aplica"),"Culminado",IF(Q24="Ejecutado",IF(AND(AC24="-",G24="Bienes"),"Culminado",IF(AC24="-","Falta informacion",IF(AND(AB24-TODAY()>=0,AB24-TODAY()<=90),"Vigente_por vencer",IF(AND(AH24<>"SI",AB24<TODAY()),"Culminado",IF(AND(AH24="SI",AB24<TODAY(),OR(AK24="Sin Registro",AL24="Sin Registro")),"Vencido",IF(AND(AH24="SI",AB24<TODAY(),AK24>AA24,AL24>AB24),"Renovado","Vigente")))))),"En tramite"))))),"-") -> Vigente | AA24: 46090 | AB24: 46449 | AC24: =IFERROR(IF(OR(AA24="-",AA24="",AB24="-",AB24=""),"-",CONCATENATE('Seguimiento OIT'!AB24-'Seguimiento OIT'!AA24+1," dias")),"-") -> 360 dias | AD24: =IFERROR(IF(Z24="Vencido",(TODAY()-AB24)+1,"-"),"-") -> - | AE24: - | AG24: https://mefgobpe1.sharepoint.com/:f:/t/DireccindelaOficinadeInfraestructuraTecnolgica/IgByz6DfXvV6SaiSj3QDxmGgAbuEEZLO-att1RGPIFhijJY?e=fhYV1S | AH24: NO | AI24: =IFERROR(IF(AH24="SI",VLOOKUP(A24,$C$4:$AL$151,15,FALSE),"-"),"Sin tramite") -> - | AJ24: =IFERROR(IF(AH24="SI",VLOOKUP(A24,$C$4:$AL$151,7,FALSE),"-"),"Sin HR") -> - | AK24: =IF(AH24="SI",IFERROR(IF(VLOOKUP(A24,$C$4:$AL$151,25,FALSE)="","Sin registro",VLOOKUP(A24,$C$4:$AL$151,25,FALSE)),"Sin registro"),"-") -> - | AL24: =IF(AH24="SI",IFERROR(IF(VLOOKUP(A24,$C$4:$AL$151,26,FALSE)="","Sin registro",VLOOKUP(A24,$C$4:$AL$151,26,FALSE)),"Sin registro"),"-") -> -
A25: REQ-2026-0022 | B25: =IF(OR(Q25="Desistido",Q25="No corresponde Atención OGTI",Q25="Para reformulación",Q25="Paralizado",Q25="-",Z25="Renovado",AND(AH25="NO",Z25="Culminado")),"NO","SI") -> NO | C25: - | D25: NO | E25: Contratación Directa | F25: Nuevo requerimiento (Apoyo técnico AUS) | G25: Bienes | H25: Adquisición de trípodes para uso de captura fotográfica de documentos históricos del Ministerio de Economía y Finanzas | I25: 109789-2026 | J25: *Tripode con aro de luz *Tripode Cenital | K25: Soporte Tecnico | L25: Napoleon Alva Vasquez | M25: Ronald Yrupailla Diaz | N25: Oficina General de Servicios al Usuario | O25: 1698 | P25: 46192 | Q25: Ejecutado | R25: - | S25: - | T25: =IFERROR(IF(OR(Q25="Ejecutado",Q25="No corresponde atención OGTI",Q25="Desistido",Q25="-",Q25="Para reformulación"),"-",IF(OR(S25="-",S25=""),"Falta fecha_estado",NETWORKDAYS(S25,TODAY(),{"02/04/2026";"03/04/2026";"30/06/2026"}))),"-") -> - | U25: Orden de Compra | V25: *0000204-2026 *0000205-2026 | W25: 46192 | X25: *INVERSIONES FOTOGRAFICAS DEL PERU S.A.C *ELECTRONICA MUSICAL SOCIEDAD ANONIMA CERRADA | Y25: Kevin Alexis Escobar Vega (OGSU) kescobar@mef.gob.pe | Z25: =IFERROR(IF(Q25="-","-",IF(Q25="Proceso de implementación/Activación/Entrega","Proceso de implementación/Activación/Entrega",IF(OR(Q25="Desistido",Q25="No corresponde atención OGTI",Q25="Para reformulación"),Q25,IF(AND(Q25="Ejecutado",AA25="No aplica",AB25="No Aplica"),"Culminado",IF(Q25="Ejecutado",IF(AND(AC25="-",G25="Bienes"),"Culminado",IF(AC25="-","Falta informacion",IF(AND(AB25-TODAY()>=0,AB25-TODAY()<=90),"Vigente_por vencer",IF(AND(AH25<>"SI",AB25<TODAY()),"Culminado",IF(AND(AH25="SI",AB25<TODAY(),OR(AK25="Sin Registro",AL25="Sin Registro")),"Vencido",IF(AND(AH25="SI",AB25<TODAY(),AK25>AA25,AL25>AB25),"Renovado","Vigente")))))),"En tramite"))))),"-") -> Culminado | AA25: - | AB25: - | AC25: =IFERROR(IF(OR(AA25="-",AA25="",AB25="-",AB25=""),"-",CONCATENATE('Seguimiento OIT'!AB25-'Seguimiento OIT'!AA25+1," dias")),"-") -> - | AD25: =IFERROR(IF(Z25="Vencido",(TODAY()-AB25)+1,"-"),"-") -> - | AE25: Validación de ofertas, fue enviada por Cesar Muñoz el 15-0626 | AF25: *Conformidad OC 204- HR 142277-2026 *Conformidad OC 205- HR 142311-2026 *03-07-26 OIT brindò su opinion favorable via correo electrònico | AG25: https://mefgobpe1.sharepoint.com/:f:/t/DireccindelaOficinadeInfraestructuraTecnolgica/IgDky8i02ETlQK-qjRtzCLJNAY7eP5CRffdnZDdkunAdmLo?e=H75nC0 | AH25: NO | AI25: =IFERROR(IF(AH25="SI",VLOOKUP(A25,$C$4:$AL$151,15,FALSE),"-"),"Sin tramite") -> - | AJ25: =IFERROR(IF(AH25="SI",VLOOKUP(A25,$C$4:$AL$151,7,FALSE),"-"),"Sin HR") -> - | AK25: =IF(AH25="SI",IFERROR(IF(VLOOKUP(A25,$C$4:$AL$151,25,FALSE)="","Sin registro",VLOOKUP(A25,$C$4:$AL$151,25,FALSE)),"Sin registro"),"-") -> - | AL25: =IF(AH25="SI",IFERROR(IF(VLOOKUP(A25,$C$4:$AL$151,26,FALSE)="","Sin registro",VLOOKUP(A25,$C$4:$AL$151,26,FALSE)),"Sin registro"),"-") -> -
